Workbook

Sheet README
A1: CVR Engineering — Phase 2 Forecast Model (Jul 2026 – Dec 2027)
A2: Generated by scripts/build_phase2_workbook.py. Companion to CVR_Model_Phase1_Baseline.xlsx.
A4: WHAT THIS IS
A5: A driver-based re-forecast built from the Phase 1 baseline. It does NOT adopt the official 2026
A6: budget as the base case (H1 came in 46% under it); the budget appears as a comparison line instead.
A7: Every output shows three views: Actual (H1), Budget (official), Forecast (driver-based).
A9: HOW THE ENGINE WORKS
A10: Revenue = FTE × 173.33 hrs/mo × utilization × blended card rate × realization
A11: Direct labor = FTE × avg wage/mo × direct-charge share (GL convention, ~92%)
A12: Burden 33.8% of wages · other OpEx at H1 run rate · overhead $17,250/mo · interest on parent note
A13: Cash: AR at DSO days of revenue; every operating dollar draws on / repays the USC parent note.
A15: TABS
... A29: COLOR KEY: blue = input · black = calculated · orange italics = assumption to confirm

Sheet Scenario Paths
A1: Scenario Paths — monthly driver values
A2: Three preset paths per driver. The Drivers tab selector picks the active row. All cells editable (blue).
A4: Path | B4: Jul-26 | C4: Aug-26 | D4: Sep-26 | E4: Oct-26 | F4: Nov-26 | G4: Dec-26 | H4: Jan-27 | I4: Feb-27 | J4: Mar-27 | K4: Apr-27 | L4: May-27 | M4: Jun-27 | N4: Jul-27 | O4: Aug-27 | P4: Sep-27 | Q4: Oct-27 | R4: Nov-27 | S4: Dec-27
A5: FTE — Base | B5: 10 | C5: 10 | D5: 10 | E5: 11 | F5: 11 | G5: 11 | H5: 12 | I5: 12 | J5: 12 | K5: 12 | L5: 12 | M5: 13 | N5: 13 | O5: 13 | P5: 13 | Q5: 13 | R5: 13 | S5: 13
A6: FTE — Upside | B6: 10 | C6: 11 | D6: 11 | E6: 12 | F6: 12 | G6: 13 | H6: 13 | I6: 14 | J6: 14 | K6: 15 | L6: 15 | M6: 15 | N6: 16 | O6: 16 | P6: 16 | Q6: 16 | R6: 16 | S6: 16
A7: FTE — Downside | B7: 10 | C7: 10 | D7: 10 | E7: 10 | F7: 10 | G7: 10 | H7: 10 | I7: 10 | J7: 10 | K7: 10 | L7: 10 | M7: 10 | N7: 10 | O7: 10 | P7: 10 | Q7: 10 | R7: 10 | S7: 10
A9: Utilization — Base | B9: 0.6 | C9: 0.61 | D9: 0.62 | E9: 0.63 | F9: 0.64 | G9: 0.65 | H9: 0.66 | I9: 0.67 | J9: 0.68 | K9: 0.69 | L9: 0.7 | M9: 0.7 | N9: 0.7 | O9: 0.7 | P9: 0.7 | Q9: 0.7 | R9: 0.7 | S9: 0.7
A10: Utilization — Upside | B10: 0.62 | C10: 0.64 | D10: 0.66 | E10: 0.68 | F10: 0.7 | G10: 0.71 | H10: 0.72 | I10: 0.73 | J10: 0.74 | K10: 0.75 | L10: 0.75 | M10: 0.75 | N10: 0.75 | O10: 0.75 | P10: 0.75 | Q10: 0.75 | R10: 0.75 | S10: 0.75
A11: Utilization — Downside | B11: 0.59 | C11: 0.59 | D11: 0.59 | E11: 0.59 | F11: 0.59 | G11: 0.59 | H11: 0.6 | I11: 0.6 | J11: 0.6 | K11: 0.6 | L11: 0.6 | M11: 0.6 | N11: 0.6 | O11: 0.6 | P11: 0.6 | Q11: 0.6 | R11: 0.6 | S11: 0.6
A13: Realization — Base | B13: 0.8 | C13: 0.81 | D13: 0.82 | E13: 0.83 | F13: 0.84 | G13: 0.85 | H13: 0.86 | I13: 0.87 | J13: 0.88 | K13: 0.89 | L13: 0.9 | M13: 0.9 | N13: 0.9 | O13: 0.9 | P13: 0.9 | Q13: 0.9 | R13: 0.9 | S13: 0.9
A14: Realization — Upside | B14: 0.82 | C14: 0.84 | D14: 0.86 | E14: 0.88 | F14: 0.9 | G14: 0.91 | H14: 0.92 | I14: 0.93 | J14: 0.94 | K14: 0.95 | L14: 0.95 | M14: 0.95 | N14: 0.95 | O14: 0.95 | P14: 0.95 | Q14: 0.95 | R14: 0.95 | S14: 0.95
A15: Realization — Downside | B15: 0.79 | C15: 0.79 | D15: 0.79 | E15: 0.79 | F15: 0.79 | G15: 0.79 | H15: 0.8 | I15: 0.8 | J15: 0.8 | K15: 0.8 | L15: 0.8 | M15: 0.8 | N15: 0.8 | O15: 0.8 | P15: 0.8 | Q15: 0.8 | R15: 0.8 | S15: 0.8
A18: Base: utilization 59%→70%, realization 79%→90%, 10→13 FTE. Upside: 75% / 95% / 16 FTE. Downside: no improvement, no hires. Hiring lead time and ramp are embedded in the FTE path — a hire contributes a full FTE the month shown.

Sheet Drivers
A1: Drivers
A2: Scenario selector (1=Base, 2=Upside, 3=Downside) | B2: 1 | C2: =CHOOSE(B2,"BASE","UPSIDE","DOWNSIDE")
A5: ($K unless noted) | B5: Jul-26 | C5: Aug-26 | D5: Sep-26 | E5: Oct-26 | F5: Nov-26 | G5: Dec-26 | H5: Jan-27 | I5: Feb-27 | J5: Mar-27 | K5: Apr-27 | L5: May-27 | M5: Jun-27 | N5: Jul-27 | O5: Aug-27 | P5: Sep-27 | Q5: Oct-27 | R5: Nov-27 | S5: Dec-27
A6: FTE (billable roster) | B6: =INDEX('Scenario Paths'!B5:B7,$B$2) | C6: =INDEX('Scenario Paths'!C5:C7,$B$2) | D6: =INDEX('Scenario Paths'!D5:D7,$B$2) | E6: =INDEX('Scenario Paths'!E5:E7,$B$2) | F6: =INDEX('Scenario Paths'!F5:F7,$B$2) | G6: =INDEX('Scenario Paths'!G5:G7,$B$2) | H6: =INDEX('Scenario Paths'!H5:H7,$B$2) | I6: =INDEX('Scenario Paths'!I5:I7,$B$2) | ... S6: =INDEX('Scenario Paths'!S5:S7,$B$2)
A7: Utilization | B7: =INDEX('Scenario Paths'!B9:B11,$B$2) | C7: =INDEX('Scenario Paths'!C9:C11,$B$2) | D7: =INDEX('Scenario Paths'!D9:D11,$B$2) | E7: =INDEX('Scenario Paths'!E9:E11,$B$2) | F7: =INDEX('Scenario Paths'!F9:F11,$B$2) | G7: =INDEX('Scenario Paths'!G9:G11,$B$2) | H7: =INDEX('Scenario Paths'!H9:H11,$B$2) | I7: =INDEX('Scenario Paths'!I9:I11,$B$2) | ... S7: =INDEX('Scenario Paths'!S9:S11,$B$2)
A8: Realization | B8: =INDEX('Scenario Paths'!B13:B15,$B$2) | C8: =INDEX('Scenario Paths'!C13:C15,$B$2) | D8: =INDEX('Scenario Paths'!D13:D15,$B$2) | E8: =INDEX('Scenario Paths'!E13:E15,$B$2) | F8: =INDEX('Scenario Paths'!F13:F15,$B$2) | G8: =INDEX('Scenario Paths'!G13:G15,$B$2) | H8: =INDEX('Scenario Paths'!H13:H15,$B$2) | I8: =INDEX('Scenario Paths'!I13:I15,$B$2) | ... S8: =INDEX('Scenario Paths'!S13:S15,$B$2)
A11: Scalar input | B11: Value | C11: Source
A12: Blended card rate ($/hr) | B12: 154.47 | C12: Phase 1 Roster & Hours (mix-weighted)
A13: Direct-labor cost / billable hr ($) | B13: 54.89 | C13: 2026 Budget: $779.8K direct labor ÷ 14,205 billable hrs
A14: Total loaded labor / FTE-month ($) | B14: 12189 | C14: 2026 Budget: $1.422M total labor cost ÷ 9.72 budget FTE ÷ 12
A15: Non-labor OpEx per month ($) | B15: 21748 | C15: 2026 Budget: OpEx less all labor & overhead, monthly
A16: Corporate overhead per month ($) | B16: 17250 | C16: 2026 Budget: $207K ÷ 12 (flat)
A17: Interest rate on parent note (APR) | B17: 0.0175 | C17: GL H1: $30.1K ÷ 6 ÷ $3.44M ×12 (budget assumes $0)
A18: DSO (days sales outstanding) | B18: 46 | C18: GL: AR $139.8K vs H1 revenue
A19: Available hours per FTE-month | B19: 173.33 | C19: 2,080 ÷ 12

Sheet Forecast P&L
A1: Forecast P&L — monthly, July 2026 – December 2027 (all figures $K)
A2: Driven entirely by the Drivers tab. Change the scenario selector or any blue input and this recomputes.
A4: ($K unless noted) | B4: Jul-26 | C4: Aug-26 | D4: Sep-26 | E4: Oct-26 | F4: Nov-26 | G4: Dec-26 | H4: Jan-27 | I4: Feb-27 | J4: Mar-27 | K4: Apr-27 | L4: May-27 | M4: Jun-27 | N4: Jul-27 | O4: Aug-27 | P4: Sep-27 | Q4: Oct-27 | R4: Nov-27 | S4: Dec-27 | T4: H2-2026 | U4: FY-2027
A5: Billable hours | B5: =Drivers!B$6*Drivers!$B$19*Drivers!B$7 | C5: =Drivers!C$6*Drivers!$B$19*Drivers!C$7 | D5: =Drivers!D$6*Drivers!$B$19*Drivers!D$7 | E5: =Drivers!E$6*Drivers!$B$19*Drivers!E$7 | F5: =Drivers!F$6*Drivers!$B$19*Drivers!F$7 | G5: =Drivers!G$6*Drivers!$B$19*Drivers!G$7 | H5: =Drivers!H$6*Drivers!$B$19*Drivers!H$7 | I5: =Drivers!I$6*Drivers!$B$19*Drivers!I$7 | ... S5: =Drivers!S$6*Drivers!$B$19*Drivers!S$7 | T5: =SUM(B5:G5) | U5: =SUM(H5:S5)
A6: Revenue | B6: =B5*Drivers!$B$12*Drivers!B$8/1000 | C6: =C5*Drivers!$B$12*Drivers!C$8/1000 | D6: =D5*Drivers!$B$12*Drivers!D$8/1000 | E6: =E5*Drivers!$B$12*Drivers!E$8/1000 | F6: =F5*Drivers!$B$12*Drivers!F$8/1000 | G6: =G5*Drivers!$B$12*Drivers!G$8/1000 | H6: =H5*Drivers!$B$12*Drivers!H$8/1000 | I6: =I5*Drivers!$B$12*Drivers!I$8/1000 | ... S6: =S5*Drivers!$B$12*Drivers!S$8/1000 | T6: =SUM(B6:G6) | U6: =SUM(H6:S6)
A7: Direct labor (billable hrs × budget rate) | B7: =B5*Drivers!$B$13/1000 | C7: =C5*Drivers!$B$13/1000 | D7: =D5*Drivers!$B$13/1000 | E7: =E5*Drivers!$B$13/1000 | F7: =F5*Drivers!$B$13/1000 | G7: =G5*Drivers!$B$13/1000 | H7: =H5*Drivers!$B$13/1000 | I7: =I5*Drivers!$B$13/1000 | ... S7: =S5*Drivers!$B$13/1000 | T7: =SUM(B7:G7) | U7: =SUM(H7:S7)
A8: Gross Profit | B8: =B6-B7 | C8: =C6-C7 | D8: =D6-D7 | E8: =E6-E7 | F8: =F6-F7 | G8: =G6-G7 | H8: =H6-H7 | I8: =I6-I7 | ... S8: =S6-S7 | T8: =SUM(B8:G8) | U8: =SUM(H8:S8)
A9: Gross margin % | B9: =B8/B6 | C9: =C8/C6 | D9: =D8/D6 | E9: =E8/E6 | F9: =F8/F6 | G9: =G8/G6 | H9: =H8/H6 | I9: =I8/I6 | ... U9: =U8/U6
A10: Indirect & other labor (total labor − direct) | B10: =Drivers!B$6*Drivers!$B$14/1000-B7 | C10: =Drivers!C$6*Drivers!$B$14/1000-C7 | D10: =Drivers!D$6*Drivers!$B$14/1000-D7 | E10: =Drivers!E$6*Drivers!$B$14/1000-E7 | F10: =Drivers!F$6*Drivers!$B$14/1000-F7 | G10: =Drivers!G$6*Drivers!$B$14/1000-G7 | H10: =Drivers!H$6*Drivers!$B$14/1000-H7 | I10: =Drivers!I$6*Drivers!$B$14/1000-I7 | ... S10: =Drivers!S$6*Drivers!$B$14/1000-S7 | T10: =SUM(B10:G10) | U10: =SUM(H10:S10)
A11: Non-labor operating expenses | B11: =Drivers!$B$15/1000 | C11: =Drivers!$B$15/1000 | D11: =Drivers!$B$15/1000 | E11: =Drivers!$B$15/1000 | F11: =Drivers!$B$15/1000 | G11: =Drivers!$B$15/1000 | H11: =Drivers!$B$15/1000 | I11: =Drivers!$B$15/1000 | ... S11: =Drivers!$B$15/1000 | T11: =SUM(B11:G11) | U11: =SUM(H11:S11)
A12: Corporate overhead allocation | B12: =Drivers!$B$16/1000 | C12: =Drivers!$B$16/1000 | D12: =Drivers!$B$16/1000 | E12: =Drivers!$B$16/1000 | F12: =Drivers!$B$16/1000 | G12: =Drivers!$B$16/1000 | H12: =Drivers!$B$16/1000 | I12: =Drivers!$B$16/1000 | ... S12: =Drivers!$B$16/1000 | T12: =SUM(B12:G12) | U12: =SUM(H12:S12)
A13: Total Operating Expenses | B13: =SUM(B10:B12) | C13: =SUM(C10:C12) | D13: =SUM(D10:D12) | E13: =SUM(E10:E12) | F13: =SUM(F10:F12) | G13: =SUM(G10:G12) | H13: =SUM(H10:H12) | I13: =SUM(I10:I12) | ... S13: =SUM(S10:S12) | T13: =SUM(B13:G13) | U13: =SUM(H13:S13)
A14: Operating Income / (Loss) | B14: =B8-B13 | C14: =C8-C13 | D14: =D8-D13 | E14: =E8-E13 | F14: =F8-F13 | G14: =G8-G13 | H14: =H8-H13 | I14: =I8-I13 | ... S14: =S8-S13 | T14: =SUM(B14:G14) | U14: =SUM(H14:S14)
A15: Interest (parent note) | B15: ='Cash & Note'!B6*Drivers!$B$17/12 | C15: ='Cash & Note'!C6*Drivers!$B$17/12 | D15: ='Cash & Note'!D6*Drivers!$B$17/12 | E15: ='Cash & Note'!E6*Drivers!$B$17/12 | F15: ='Cash & Note'!F6*Drivers!$B$17/12 | G15: ='Cash & Note'!G6*Drivers!$B$17/12 | H15: ='Cash & Note'!H6*Drivers!$B$17/12 | I15: ='Cash & Note'!I6*Drivers!$B$17/12 | ... S15: ='Cash & Note'!S6*Drivers!$B$17/12 | T15: =SUM(B15:G15) | U15: =SUM(H15:S15)
A16: Net Income / (Loss) | B16: =B14-B15 | C16: =C14-C15 | D16: =D14-D15 | E16: =E14-E15 | F16: =F14-F15 | G16: =G14-G15 | H16: =H14-H15 | I16: =I14-I15 | ... S16: =S14-S15 | T16: =SUM(B16:G16) | U16: =SUM(H16:S16)
A17: OILI return % (OI − interest) ÷ revenue | B17: =(B14-B15)/B6 | C17: =(C14-C15)/C6 | D17: =(D14-D15)/D6 | E17: =(E14-E15)/E6 | F17: =(F14-F15)/F6 | G17: =(G14-G15)/G6 | H17: =(H14-H15)/H6 | I17: =(I14-I15)/I6 | ... U17: =(U14-U15)/U6
A19: Cost structure reconciled to the 2026 CVR Budget (finance): direct labor = billable hours × $54.89; total labor is fixed per FTE, so utilization gains flow to Operating Income. At the budget operating point (9.72 FTE, 70% util, ~$142.85 realized) this reproduces the budget's $104.1K GP and $11.6K OI/month.
A20: BUDGET (finance, flat monthly): Revenue $169.1K · Direct labor $65.0K · GP $104.1K · OpEx $92.5K · Operating Income $11.6K · Interest $0 · Net Income $11.6K. Full monthly compare on the 'vs Budget' tab.

Sheet vs Budget
A1: Forecast vs 2026 Budget (finance) — H2-2026, line by line ($K)
A2: Budget = flat monthly per the 2026 CVR Budget V5. Forecast = active scenario from Forecast P&L. Δ = Forecast − Budget.
A4: H2-2026 ($K) | B4: Forecast | C4: Budget | D4: Δ (Fcst − Bud) | E4: Δ %
A5: Revenue | B5: =SUM('Forecast P&L'!B6:G6) | C5: 1014.6 | D5: =B5-C5 | E5: =IF(C5=0,"n/a",B5/C5-1)
A6: Direct labor | B6: =SUM('Forecast P&L'!B7:G7) | C6: 389.9 | D6: =B6-C6 | E6: =IF(C6=0,"n/a",B6/C6-1)
A7: Gross Profit | B7: =SUM('Forecast P&L'!B8:G8) | C7: 624.7 | D7: =B7-C7 | E7: =IF(C7=0,"n/a",B7/C7-1)
A8: Total Operating Expenses | B8: =SUM('Forecast P&L'!B13:G13) | C8: 555 | D8: =B8-C8 | E8: =IF(C8=0,"n/a",B8/C8-1)
A9: Operating Income | B9: =SUM('Forecast P&L'!B14:G14) | C9: 69.7 | D9: =B9-C9 | E9: =IF(C9=0,"n/a",B9/C9-1)
A10: Interest | B10: =SUM('Forecast P&L'!B15:G15) | C10: 0 | D10: =B10-C10 | E10: =IF(C10=0,"n/a",B10/C10-1)
A11: Net Income | B11: =SUM('Forecast P&L'!B16:G16) | C11: 69.7 | D11: =B11-C11 | E11: =IF(C11=0,"n/a",B11/C11-1)
A13: Full monthly budget (flat) for reference:
A14: Budget $K | B14: Jul-26 | C14: Aug-26 | D14: Sep-26 | E14: Oct-26 | F14: Nov-26 | G14: Dec-26
A15: Revenue | B15: 169.1 | C15: 169.1 | D15: 169.1 | E15: 169.1 | F15: 169.1 | G15: 169.1
A16: Direct labor | B16: 65 | C16: 65 | D16: 65 | E16: 65 | F16: 65 | G16: 65
A17: Gross Profit | B17: 104.1 | C17: 104.1 | D17: 104.1 | E17: 104.1 | F17: 104.1 | G17: 104.1
A18: Total Operating Expenses | B18: 92.5 | C18: 92.5 | D18: 92.5 | E18: 92.5 | F18: 92.5 | G18: 92.5
A19: Operating Income | B19: 11.6 | C19: 11.6 | D19: 11.6 | E19: 11.6 | F19: 11.6 | G19: 11.6
A20: Net Income | B20: 11.6 | C20: 11.6 | D20: 11.6 | E20: 11.6 | F20: 11.6 | G20: 11.6
A22: Budget carries $0 interest; the forecast accrues ~$5K/mo on the parent note — so forecast Net Income trails
A23: budget by roughly that amount even at matched operating performance.
A24: The full-year budget ($2,029K revenue / +$139K NI) is a flat 1/12 spread; H1 landed 46% under it, so the
A25: meaningful compare is H2 forward — shown above — plus the FY landing on the FY Summary tab.

Sheet Cash & Note
A1: Cash & Parent-Note Roll-Forward (all figures $K)
A2: CVR holds no cash: deficits draw on the USC parent note, surpluses repay it. Interest accrues on the opening balance.
A4: ($K unless noted) | B4: Jul-26 | C4: Aug-26 | D4: Sep-26 | E4: Oct-26 | F4: Nov-26 | G4: Dec-26 | H4: Jan-27 | I4: Feb-27 | J4: Mar-27 | K4: Apr-27 | L4: May-27 | M4: Jun-27 | N4: Jul-27 | O4: Aug-27 | P4: Sep-27 | Q4: Oct-27 | R4: Nov-27 | S4: Dec-27
A5: Net Income / (Loss) | B5: ='Forecast P&L'!B16 | C5: ='Forecast P&L'!C16 | D5: ='Forecast P&L'!D16 | E5: ='Forecast P&L'!E16 | F5: ='Forecast P&L'!F16 | G5: ='Forecast P&L'!G16 | H5: ='Forecast P&L'!H16 | I5: ='Forecast P&L'!I16 | ... S5: ='Forecast P&L'!S16
A6: Opening note balance | B6: 3436.6 | C6: =B10 | D6: =C10 | E6: =D10 | F6: =E10 | G6: =F10 | H6: =G10 | I6: =H10 | J6: =I10 | ... S6: =R10
A7: AR balance (DSO × revenue) | B7: ='Forecast P&L'!B6*Drivers!$B$18/30.4 | C7: ='Forecast P&L'!C6*Drivers!$B$18/30.4 | D7: ='Forecast P&L'!D6*Drivers!$B$18/30.4 | E7: ='Forecast P&L'!E6*Drivers!$B$18/30.4 | F7: ='Forecast P&L'!F6*Drivers!$B$18/30.4 | G7: ='Forecast P&L'!G6*Drivers!$B$18/30.4 | H7: ='Forecast P&L'!H6*Drivers!$B$18/30.4 | I7: ='Forecast P&L'!I6*Drivers!$B$18/30.4 | ... S7: ='Forecast P&L'!S6*Drivers!$B$18/30.4
A8: Δ AR | B8: =B7-139.8 | C8: =C7-B7 | D8: =D7-C7 | E8: =E7-D7 | F8: =F7-E7 | G8: =G7-F7 | H8: =H7-G7 | I8: =I7-H7 | J8: =J7-I7 | ... S8: =S7-R7
A9: Operating cash flow | B9: =B5-B8 | C9: =C5-C8 | D9: =D5-D8 | E9: =E5-E8 | F9: =F5-F8 | G9: =G5-G8 | H9: =H5-H8 | I9: =I5-I8 | ... S9: =S5-S8
A10: Closing note balance | B10: =B6-B9 | C10: =C6-C9 | D10: =D6-D9 | E10: =E6-E9 | F10: =F6-F9 | G10: =G6-G9 | H10: =H6-H9 | I10: =I6-I9 | ... S10: =S6-S9
A12: Opening note balance 6/30/26: $3,436.6K. The official budget expects a $157.8K paydown by year-end; this tab shows what the driver-based forecast actually implies.

Sheet Backlog & Pipeline
A1: Backlog, Pipeline, and Forecast Coverage (all figures $K)
A2: Backlog = remaining PO value on active jobs (KPI scorecard 7/11/26). Pipeline = pending bids × win probability.
A4: Job | B4: Customer / name | C4: PO value | D4: Billed to date | E4: Remaining | F4: Sched. finish | G4: Note
A5: 001-0001 | B5: DTE — Catalina Conversion Ph 3 | C5: 838.451 | D5: 806.331 | E5: =C5-D5 | F5: 2026 | G5: construction support tail
A6: 001-0003 | B6: DTE — New Baltimore Conversion | C6: 1428.796 | D6: 1216.312 | E6: =C6-D6 | F6: Dec-27 | G6: 64% complete
A7: 005-0004 | B7: Consumers — 2026 HVD Line Sensors | C7: 130.493 | D7: 71.268 | E7: =C7-D7 | F7: Oct-26 | G7: 77% complete
A8: 016-0001 | B8: Cloverland — Manistique Pump Stn | C8: 111.51 | D8: 106.628 | E8: =C8-D8 | F8: Sep-26 | G8: 99% — cost overrun job
A9: 017-0003 | B9: CenterPoint — Gateway 69kV | C9: 203.015 | D9: 131.23 | E9: =C9-D9 | F9: Aug-26 | G9: 65% complete
A10: 017-0004 | B10: CenterPoint — Rockport 69kV | C10: 96.712 | D10: 81.692 | E10: =C10-D10 | F10: Aug-26 | G10: 88% complete
A11: 017-0005 | B11: CenterPoint — Angel Mounds 69kV | C11: 96.987 | D11: 95.148 | E11: =C11-D11 | F11: Oct-26 | G11: 88% complete
A12: 017-0006 | B12: CenterPoint — Northwest 69kV | C12: 110.555 | D12: 4.365 | E12: =C12-D12 | F12: Aug-27 | G12: 13% — early
A13: 017-0007 | B13: CenterPoint — Leonard Rd 69kV | C13: 199.994 | D13: 6.739 | E13: =C13-D13 | F13: Oct-27 | G13: 17% — early
A14: (new) | B14: Consumers — 2026 Pole Replacements | C14: 300 | D14: 0 | E14: =C14-D14 | F14: Dec-27 | G14: WON — award $300K; EPC-paired $3.45M
B15: Total backlog remaining | E15: =SUM(E5:E14)
A17: PIPELINE — pending bids (CVR scope)
A18: Bid | B18: Customer | C18: CVR value | D18: Win prob. | E18: Expected | F18: Expected award
A19: Frontier Make Ready | B19: Steuben County REMC | C19: 100 | D19: 0.5 | E19: =C19*D19 | F19: Q3-26
A20: Jacksonburg–Gateway (EPC-paired $3.55M) | B20: Hoosier Energy | C20: 160 | D20: 0.5 | E20: =C20*D20 | F20: Q4-26
A21: Rosehill–Rockport (EPC-paired $5.59M) | B21: Hoosier Energy | C21: 290 | D21: 0.5 | E21: =C21*D21 | F21: Q4-26
A22: Joint Use Audit | B22: Lansing Board of Water & Light | C22: 1350 | D22: 0.5 | E22: =C22*D22 | F22: Q4-26
A23: Renaissance 345kV Substation (ON HOLD) | B23: DTE Energy | C23: 0 | D23: 0 | E23: =C23*D23 | F23: hold
B24: Total probability-weighted pipeline | E24: =SUM(E19:E23)
A26: COVERAGE CHECK
A27: Forecast revenue, Jul-26 – Dec-27 | B27: ='Forecast P&L'!T6+'Forecast P&L'!U6
A28: Booked + expected work (backlog + weighted pipeline) | B28: =E15+E24
A29: Coverage ratio | B29: =B28/B27
A31: Coverage below 100% is normal at an 18-month horizon — the gap is work still to be won. But if coverage falls much below ~60%, the forecast is leaning on unidentified sales; treat the gap as the BD target: it quantifies how much new work Estimating must originate beyond the current bid list.

Sheet FY Summary
A1: Fiscal-Year Summary — Actual · Budget · Forecast (all figures $K)
A2: FY2026 = H1 actual (GL) + H2 forecast. FY2027 = forecast vs the $6M Year-2 divisional goal.
A4: FY2026 | B4: H1 Actual | C4: H2 Forecast | D4: FY Total | E4: Official Budget | F4: FY vs Budget
A5: Revenue | B5: 551 | C5: ='Forecast P&L'!T6 | D5: =B5+C5 | E5: 2029.1 | F5: =D5-E5
A6: Gross Profit | B6: 122.5 | C6: ='Forecast P&L'!T8 | D6: =B6+C6 | E6: 1249.4 | F6: =D6-E6
A7: Operating Income / (Loss) | B7: -290.5 | C7: ='Forecast P&L'!T14 | D7: =B7+C7 | E7: 139.4 | F7: =D7-E7
A8: Interest | B8: 30.1 | C8: ='Forecast P&L'!T15 | D8: =B8+C8 | E8: 0 | F8: =D8-E8
A9: Net Income / (Loss) | B9: -320.5 | C9: ='Forecast P&L'!T16 | D9: =B9+C9 | E9: 139.4 | F9: =D9-E9
A10: OILI return % (FY) | B10: =(D7-D8)/D5
A11: Note balance at 12/31/26 | B11: ='Cash & Note'!G10
A13: FY2027 | B13: Forecast | C13: Year-2 Goal | D13: % of goal
A14: Revenue | B14: ='Forecast P&L'!U6 | C14: 6000 | D14: =B14/C14
A15: Gross Profit | B15: ='Forecast P&L'!U8
A16: Operating Income / (Loss) | B16: ='Forecast P&L'!U14
A17: Net Income / (Loss) | B17: ='Forecast P&L'!U16
A18: OILI return % (FY27) | B18: =('Forecast P&L'!U14-'Forecast P&L'!U15)/'Forecast P&L'!U6
A19: Note balance at 12/31/27 | B19: ='Cash & Note'!S10
A21: The gap between FY27 forecast revenue and the $6M goal is structural (billable capacity), not effort: closing it requires the hiring ramp AND winning EPC-paired engineering at scale — see the utilization × realization grid in the Phase 1 workbook for the per-FTE ceiling math.

Sheet EPC At-Scale Model
A1: Revised Business Model — EPC at Scale: CVR earns engineering + material margin
A2: Steady-state illustration at $150M/yr EPC (NOT the near-term forecast). CVR takes engineering scope + material margin; HWC keeps equipment + labor margin. Blue = input; grey = calculated.
A4: DRIVERS — edit the blue cells
A5: EPC program volume ($M/yr) | B5: 150 | C5: Consolidated EPC run-rate (HWC + CVR)
A6: CVR materials share of EPC | B6: 0.35 | C6: Materials through CVR; major equipment stays with HWC
A7: Material gross margin | B7: 0.13 | C7: CVR procurement markup on materials
A8: Procurement + WC carry (pts of flow) | B8: 0.02 | C8: Purchasing staff + working-capital carry
A9: Engineering pull-through (% of EPC) | B9: 0.08 | C9: CVR engineering scope at this scale
A10: Engineering gross margin | B10: 0.6 | C10: Engineering revenue less direct labor
A11: Engineering operating margin | B11: 0.15 | C11: Engineering OI as % of eng revenue, at scale
A12: Working-capital carry (days of flow) | B12: 45 | C12: Days from paying suppliers to reimbursement
A14: MATERIAL PROCUREMENT — CVR as principal ($M)
A15: Materials revenue (billed) | B15: =B5*B6
A16: Materials cost (COGS, at cost) | B16: =B15*(1-B7)
A17: Material gross margin | B17: =B15*B7 | C17: =B7
A18: Procurement + working-capital cost | B18: =B15*B8
A19: Material net contribution | B19: =B17-B18
A21: ENGINEERING SERVICES ($M)
A22: Engineering revenue | B22: =B5*B9
A23: Engineering gross profit | B23: =B22*B10
A24: Engineering operating income | B24: =B22*B11
A25: Engineering OpEx (= GP − OI) | B25: =B23-B24
A27: COMBINED CVR — STEADY STATE ($M)
A28: CVR revenue — gross / principal basis | B28: =B22+B15 | C28: CVR takes title to materials
A29: CVR revenue — managed-margin basis | B29: =B22+B17 | C29: engineering + material margin
A30: CVR gross profit | B30: =B23+B17
A31: Total operating cost | B31: =B25+B18
A32: CVR operating income (OILI) | B32: =B30-B31
A33: OI margin — managed revenue | B33: =B32/B29
A34: OI margin — gross revenue | B34: =B32/B28
A35: Working-capital requirement ($M) | B35: =B15*B12/365 | C35: materials flow × carry days
A37: CONTEXT vs TODAY & THE YEAR-2 GOAL ($M)
A38: CVR revenue today (managed, ~FY26) | B38: 1.42 | C38: current baseline
A39: This model — managed revenue | B39: =B29
A40: Year-2 goal operating profit ($6M × 20%) | B40: 1.2
A41: This model — operating income | B41: =B32
A42: Multiple of the Year-2 goal profit | B42: =B32/B40
A44: PER-PROJECT ILLUSTRATION — a $3.45M EPC job ($M)
A45: EPC job value | B45: 3.45 | C45: Consumers-paired size
A46: Materials (share of job) | B46: =B45*B6
...

Sheet Checks
A1: Integrity checks
A4: Check | B4: Model | C4: Expected | D4: Status
A5: H1 revenue anchor ($K) | B5: ='FY Summary'!B5 | C5: 551 | D5: =IF(ABS(B5-C5)<=0.5,"TIES","CHECK")
A6: H1 net income anchor ($K) | B6: ='FY Summary'!B9 | C6: -320.5 | D6: =IF(ABS(B6-C6)<=0.5,"TIES","CHECK")
A7: Backlog remaining total ($K) | B7: ='Backlog & Pipeline'!E15 | C7: 696.8 | D7: =IF(ABS(B7-C7)<=2.0,"TIES","CHECK")
A8: Note roll integrity: Dec-27 close = open − Σ op cash | B8: ='Cash & Note'!S10 | C8: =3436.6-SUM('Cash & Note'!B9:S9) | D8: =IF(ABS(B8-C8)<=0.1,"TIES","CHECK")
A9: Coverage ratio computed | B9: ='Backlog & Pipeline'!B28 | C9: >0 expected | D9: =IF(B9>0,"OK","CHECK")
A11: MODEL LIMITS (read before presenting)
A12: • Revenue is capacity-driven; the coverage check disciplines it against booked work, but it is not a job-by-job burn schedule.
A13: • Direct-charge share (92%) mirrors the GL convention; when salary detail arrives, split wages properly by person.
A14: • The FTE path assumes hires are productive in month one — add ramp months per hire if that proves optimistic.
A15: • Pipeline probabilities are placeholders at the 2026 win rate (67%) or 50% — Estimating should own these numbers.
A16: • Escalation is off (card rate and wages flat through 2027) — turn on via the scalar inputs when the 2027 rate sheet lands.

Sheet Coverage Chart
A1: Forecast & work coverage — with pipeline toggle
A2: Native chart wired to live cells. Set the toggle to 0 to see booked backlog only; edit job remainders or bid probabilities and everything redraws.
A3: Include weighted pipeline? (1 = yes, 0 = no) | B3: 1
A5: Coverage of forecast | B5: =(SUM(B35:S35)+SUM(B40:S40))/SUM(B41:S41)
A6: Gap to originate ($K) | B6: =SUM(B41:S41)-SUM(B35:S35)-SUM(B40:S40)
A23: CHART DATA ($K/month) — formulas reference Backlog & Pipeline and Forecast P&L
A24: Month | B24: Jul-26 | C24: Aug-26 | D24: Sep-26 | E24: Oct-26 | F24: Nov-26 | G24: Dec-26 | H24: Jan-27 | I24: Feb-27 | J24: Mar-27 | K24: Apr-27 | L24: May-27 | M24: Jun-27 | N24: Jul-27 | O24: Aug-27 | P24: Sep-27 | Q24: Oct-27 | R24: Nov-27 | S24: Dec-27
A25: burn: DTE — Catalina Conversion Ph 3 | B25: ='Backlog & Pipeline'!$E5/6 | C25: ='Backlog & Pipeline'!$E5/6 | D25: ='Backlog & Pipeline'!$E5/6 | E25: ='Backlog & Pipeline'!$E5/6 | F25: ='Backlog & Pipeline'!$E5/6 | G25: ='Backlog & Pipeline'!$E5/6 | H25: 0 | I25: 0 | J25: 0 | K25: 0 | L25: 0 | M25: 0 | N25: 0 | O25: 0 | P25: 0 | Q25: 0 | R25: 0 | S25: 0
A26: burn: DTE — New Baltimore Conversion | B26: ='Backlog & Pipeline'!$E6/18 | C26: ='Backlog & Pipeline'!$E6/18 | D26: ='Backlog & Pipeline'!$E6/18 | E26: ='Backlog & Pipeline'!$E6/18 | F26: ='Backlog & Pipeline'!$E6/18 | G26: ='Backlog & Pipeline'!$E6/18 | H26: ='Backlog & Pipeline'!$E6/18 | I26: ='Backlog & Pipeline'!$E6/18 | ... S26: ='Backlog & Pipeline'!$E6/18
A27: burn: Consumers — 2026 HVD Line Sensors | B27: ='Backlog & Pipeline'!$E7/4 | C27: ='Backlog & Pipeline'!$E7/4 | D27: ='Backlog & Pipeline'!$E7/4 | E27: ='Backlog & Pipeline'!$E7/4 | F27: 0 | G27: 0 | H27: 0 | I27: 0 | J27: 0 | K27: 0 | L27: 0 | M27: 0 | N27: 0 | O27: 0 | P27: 0 | Q27: 0 | R27: 0 | S27: 0
A28: burn: Cloverland — Manistique Pump Stn | B28: ='Backlog & Pipeline'!$E8/3 | C28: ='Backlog & Pipeline'!$E8/3 | D28: ='Backlog & Pipeline'!$E8/3 | E28: 0 | F28: 0 | G28: 0 | H28: 0 | I28: 0 | J28: 0 | K28: 0 | L28: 0 | M28: 0 | N28: 0 | O28: 0 | P28: 0 | Q28: 0 | R28: 0 | S28: 0
A29: burn: CenterPoint — Gateway 69kV | B29: ='Backlog & Pipeline'!$E9/2 | C29: ='Backlog & Pipeline'!$E9/2 | D29: 0 | E29: 0 | F29: 0 | G29: 0 | H29: 0 | I29: 0 | J29: 0 | K29: 0 | L29: 0 | M29: 0 | N29: 0 | O29: 0 | P29: 0 | Q29: 0 | R29: 0 | S29: 0
A30: burn: CenterPoint — Rockport 69kV | B30: ='Backlog & Pipeline'!$E10/2 | C30: ='Backlog & Pipeline'!$E10/2 | D30: 0 | E30: 0 | F30: 0 | G30: 0 | H30: 0 | I30: 0 | J30: 0 | K30: 0 | L30: 0 | M30: 0 | N30: 0 | O30: 0 | P30: 0 | Q30: 0 | R30: 0 | S30: 0
A31: burn: CenterPoint — Angel Mounds 69kV | B31: ='Backlog & Pipeline'!$E11/4 | C31: ='Backlog & Pipeline'!$E11/4 | D31: ='Backlog & Pipeline'!$E11/4 | E31: ='Backlog & Pipeline'!$E11/4 | F31: 0 | G31: 0 | H31: 0 | I31: 0 | J31: 0 | K31: 0 | L31: 0 | M31: 0 | N31: 0 | O31: 0 | P31: 0 | Q31: 0 | R31: 0 | S31: 0
A32: burn: CenterPoint — Northwest 69kV | B32: ='Backlog & Pipeline'!$E12/14 | C32: ='Backlog & Pipeline'!$E12/14 | D32: ='Backlog & Pipeline'!$E12/14 | E32: ='Backlog & Pipeline'!$E12/14 | F32: ='Backlog & Pipeline'!$E12/14 | G32: ='Backlog & Pipeline'!$E12/14 | H32: ='Backlog & Pipeline'!$E12/14 | I32: ='Backlog & Pipeline'!$E12/14 | ... O32: ='Backlog & Pipeline'!$E12/14 | P32: 0 | Q32: 0 | R32: 0 | S32: 0
A33: burn: CenterPoint — Leonard Rd 69kV | B33: ='Backlog & Pipeline'!$E13/16 | C33: ='Backlog & Pipeline'!$E13/16 | D33: ='Backlog & Pipeline'!$E13/16 | E33: ='Backlog & Pipeline'!$E13/16 | F33: ='Backlog & Pipeline'!$E13/16 | G33: ='Backlog & Pipeline'!$E13/16 | H33: ='Backlog & Pipeline'!$E13/16 | I33: ='Backlog & Pipeline'!$E13/16 | ... Q33: ='Backlog & Pipeline'!$E13/16 | R33: 0 | S33: 0
A34: burn: Consumers — 2026 Pole Replacements | B34: ='Backlog & Pipeline'!$E14/18 | C34: ='Backlog & Pipeline'!$E14/18 | D34: ='Backlog & Pipeline'!$E14/18 | E34: ='Backlog & Pipeline'!$E14/18 | F34: ='Backlog & Pipeline'!$E14/18 | G34: ='Backlog & Pipeline'!$E14/18 | H34: ='Backlog & Pipeline'!$E14/18 | I34: ='Backlog & Pipeline'!$E14/18 | ... S34: ='Backlog & Pipeline'!$E14/18
A35: Booked backlog | B35: =SUM(B25:B34) | C35: =SUM(C25:C34) | D35: =SUM(D25:D34) | E35: =SUM(E25:E34) | F35: =SUM(F25:F34) | G35: =SUM(G25:G34) | H35: =SUM(H25:H34) | I35: =SUM(I25:I34) | ... S35: =SUM(S25:S34)
A36: bid: Frontier Make Ready | B36: 0 | C36: 0 | D36: ='Backlog & Pipeline'!$C19*'Backlog & Pipeline'!$D19/6 | E36: ='Backlog & Pipeline'!$C19*'Backlog & Pipeline'!$D19/6 | F36: ='Backlog & Pipeline'!$C19*'Backlog & Pipeline'!$D19/6 | G36: ='Backlog & Pipeline'!$C19*'Backlog & Pipeline'!$D19/6 | H36: ='Backlog & Pipeline'!$C19*'Backlog & Pipeline'!$D19/6 | I36: ='Backlog & Pipeline'!$C19*'Backlog & Pipeline'!$D19/6 | J36: 0 | K36: 0 | L36: 0 | M36: 0 | N36: 0 | O36: 0 | P36: 0 | Q36: 0 | R36: 0 | S36: 0
A37: bid: Jacksonburg–Gateway (EPC-paired $3 | B37: 0 | C37: 0 | D37: 0 | E37: 0 | F37: ='Backlog & Pipeline'!$C20*'Backlog & Pipeline'!$D20/12 | G37: ='Backlog & Pipeline'!$C20*'Backlog & Pipeline'!$D20/12 | H37: ='Backlog & Pipeline'!$C20*'Backlog & Pipeline'!$D20/12 | I37: ='Backlog & Pipeline'!$C20*'Backlog & Pipeline'!$D20/12 | J37: ='Backlog & Pipeline'!$C20*'Backlog & Pipeline'!$D20/12 | K37: ='Backlog & Pipeline'!$C20*'Backlog & Pipeline'!$D20/12 | L37: ='Backlog & Pipeline'!$C20*'Backlog & Pipeline'!$D20/12 | M37: ='Backlog & Pipeline'!$C20*'Backlog & Pipeline'!$D20/12 | ... Q37: ='Backlog & Pipeline'!$C20*'Backlog & Pipeline'!$D20/12 | R37: 0 | S37: 0
A38: bid: Rosehill–Rockport (EPC-paired $5.5 | B38: 0 | C38: 0 | D38: 0 | E38: 0 | F38: ='Backlog & Pipeline'!$C21*'Backlog & Pipeline'!$D21/12 | G38: ='Backlog & Pipeline'!$C21*'Backlog & Pipeline'!$D21/12 | H38: ='Backlog & Pipeline'!$C21*'Backlog & Pipeline'!$D21/12 | I38: ='Backlog & Pipeline'!$C21*'Backlog & Pipeline'!$D21/12 | J38: ='Backlog & Pipeline'!$C21*'Backlog & Pipeline'!$D21/12 | K38: ='Backlog & Pipeline'!$C21*'Backlog & Pipeline'!$D21/12 | L38: ='Backlog & Pipeline'!$C21*'Backlog & Pipeline'!$D21/12 | M38: ='Backlog & Pipeline'!$C21*'Backlog & Pipeline'!$D21/12 | ... Q38: ='Backlog & Pipeline'!$C21*'Backlog & Pipeline'!$D21/12 | R38: 0 | S38: 0
A39: bid: Joint Use Audit | B39: 0 | C39: 0 | D39: 0 | E39: 0 | F39: 0 | G39: ='Backlog & Pipeline'!$C22*'Backlog & Pipeline'!$D22/18 | H39: ='Backlog & Pipeline'!$C22*'Backlog & Pipeline'!$D22/18 | I39: ='Backlog & Pipeline'!$C22*'Backlog & Pipeline'!$D22/18 | J39: ='Backlog & Pipeline'!$C22*'Backlog & Pipeline'!$D22/18 | K39: ='Backlog & Pipeline'!$C22*'Backlog & Pipeline'!$D22/18 | L39: ='Backlog & Pipeline'!$C22*'Backlog & Pipeline'!$D22/18 | M39: ='Backlog & Pipeline'!$C22*'Backlog & Pipeline'!$D22/18 | N39: ='Backlog & Pipeline'!$C22*'Backlog & Pipeline'!$D22/18 | ... S39: ='Backlog & Pipeline'!$C22*'Backlog & Pipeline'!$D22/18
A40: Weighted pipeline (× toggle) | B40: =SUM(B36:B39)*$B$3 | C40: =SUM(C36:C39)*$B$3 | D40: =SUM(D36:D39)*$B$3 | E40: =SUM(E36:E39)*$B$3 | F40: =SUM(F36:F39)*$B$3 | G40: =SUM(G36:G39)*$B$3 | H40: =SUM(H36:H39)*$B$3 | I40: =SUM(I36:I39)*$B$3 | ... S40: =SUM(S36:S39)*$B$3
A41: Forecast revenue | B41: ='Forecast P&L'!B6 | C41: ='Forecast P&L'!C6 | D41: ='Forecast P&L'!D6 | E41: ='Forecast P&L'!E6 | F41: ='Forecast P&L'!F6 | G41: ='Forecast P&L'!G6 | H41: ='Forecast P&L'!H6 | I41: ='Forecast P&L'!I6 | ... S41: ='Forecast P&L'!S6
